2017-01-11 17:02:09 zopkio [INFO] Starting zopkio
2017-01-11 17:02:09 naarad [INFO] Available graphing modules:  
2017-01-11 17:02:09 zopkio.test_runner [INFO] Setting up configuration: single execution
2017-01-11 17:02:36 zopkio.remote_host_helper [ERROR] Traceback (most recent call last):
  File "/home/riaps/riaps_apps/checkDiscoveryService.py", line 16, in <module>
    raise FileNotFoundError(errno.ENOENT, os.strerror(errno.ENOENT), "riaps-disco")
FileNotFoundError: [Errno 2] No such file or directory: 'riaps-disco'

2017-01-11 17:02:39 naarad.utils [WARNING] /home/istvan/work/riaps-pycom/tests/testPubSub/test_1_1_local/naarad.cfg : file does not exist.
2017-01-11 17:02:39 naarad.utils [WARNING] /home/istvan/work/riaps-pycom/tests/testPubSub/test_1_1_local/naarad.cfg : file does not exist.
2017-01-11 17:02:39 naarad.utils [WARNING] /home/istvan/work/riaps-pycom/tests/testPubSub/test_1_1_local/naarad.cfg : file does not exist.
2017-01-11 17:02:39 zopkio.test_runner [INFO] Execution of configuration: single execution complete
2017-01-11 17:02:39 zopkio.test_runner [INFO] test_pub_send----failed
2017-01-11 17:02:39 zopkio.test_runner [INFO] ['IndexError: list index out of range\n']
2017-01-11 17:02:39 zopkio.test_runner [INFO] test_reach_discovery----failed
2017-01-11 17:02:39 zopkio.test_runner [INFO] ['ParamikoError: Failed to start\nTraceback (most recent call last):\n  File "/home/riaps/riaps_apps/checkDiscoveryService.py", line 16, in <module>\n    raise FileNotFoundError(errno.ENOENT, os.strerror(errno.ENOENT), "riaps-disco")\nFileNotFoundError: [Errno 2] No such file or directory: \'riaps-disco\'\n\n']
2017-01-11 17:02:39 zopkio [INFO] Exiting zopkio
